Workbook

Sheet INSTRUCOES
A1: Fluxo de Caixa Diário — instruções rápidas
A3: Projeto | B3: SÃO FRANCISCO DE PAULA - RS | D3: Qtd. casas | E3: 64
A5: 1. | B5: Use a aba BASE_CAIXA como base única para tabela dinâmica e análises.
A6: 2. | B6: Preencha as colunas amarelas: Fornecedor, Lote_Pagto, Documento, Data_Prevista, Data_Realizada e Valor_Realizado.
A7: 3. | B7: As linhas 251–257 e 259–266 foram classificadas como GESTÃO LOCAL.
A8: 4. | B8: As linhas 269–271 foram classificadas como DESPESAS ACESSÓRIAS.
A9: 5. | B9: As linhas 273–277 foram classificadas como CAPITAL DE GIRO.
A10: 6. | B10: A aba FLUXO_DIARIO soma previsto pendente e realizado por dia.
A11: 7. | B11: A aba SAUDE_FLUXO mostra indicadores de suficiência, saldo mínimo e dias críticos.
A14: Amarelo = edição manual | C14: Cinza claro = cálculo
A16: 6. | B16: Nova arquitetura financeira: BASE_CAIXA (gerencial) + AGENDA_BANCARIA (o que deve aparecer no banco) + EXTRATO_IMPORTADO (onde você cola o extrato) + CONCILIACAO (resumo).
A17: 7. | B17: Na BASE_CAIXA, preencha principalmente: Fornecedor, Lote_Pagto, Documento, Forma_Pagamento, Meio_Financeiro, Conta_Origem e Data_Vencimento.
A18: 8. | B18: Para cartão de crédito, a Data_Vencimento deve refletir a data da fatura/parcela; a Data_Compensacao_Prevista é o dia em que você espera enxergar o efeito no extrato/fatura.
A19: 9. | B19: Cole o extrato bruto na aba EXTRATO_IMPORTADO a partir da linha 2. Depois preencha o ID_Concil_Manual com a chave da AGENDA_BANCARIA quando identificar o lançamento.
A20: 10. | B20: A aba CONCILIACAO resume quantos eventos estão conciliados, pendentes, vencidos, divergentes e quantos movimentos do extrato vieram sem previsão.

Sheet BASE_CAIXA
A1: ID | B1: Projeto | C1: Tipo_Fluxo | D1: Grupo | E1: Apropriacao | F1: Tipo | G1: Item | H1: Fornecedor | I1: Lote_Pagto | J1: Documento | K1: Data_Prevista | L1: Data_Realizada | M1: Valor_Realizado | N1: Forma_Pagamento | O1: Meio_Financeiro | P1: Conta_Origem | Q1: Data_Vencimento | R1: Categoria | S1: Conta_Sintetica | T1: Conta_Analitica | U1: Observacoes | V1: Linha_Origem | W1: Quinzena | X1: Periodo_Inicio | Y1: Periodo_Fim | Z1: Valor_Previsto | AA1: Valor_Considerado | AB1: Status | AC1: %_Quinzena | AD1: Valor_Origem_Linha | AE1: Quant_Total_Origem | AF1: Unidade_Origem | AG1: Custo_Unit_Origem | AH1: Info_Origem_Extra | AI1: Aba_Origem | AJ1: Data_Compensacao_Prevista | AK1: Conciliar? | AL1: ID_Concil | AM1: Historico_Padrao_Extrato
A2: 1 | B2: SÃO FRANCISCO DE PAULA - RS | C2: Entrada | D2: RECEITAS | E2: RECEITAS | F2: RECEITA CONTRATUAL | G2: MEDIÇÃO CONTRATUAL | H2: FM SOLUÇÕES EM BEBIDAS | I2: INVEST_01 | K2: 46080 | L2: 2702 | M2: 720000 | N2: PIX | Q2: =IF(K2="","",K2) -> 46080 | R2: MEDIÇÃO CONTRATUAL | S2: Entrada | MEDIÇÃO CONTRATUAL | T2: Entrada | RECEITAS | RECEITA CONTRATUAL | U2: aporte investidor | V2: 283 | W2: Q1 | X2: 46090 | Y2: 46101 | Z2: 720000 | AA2: =IF(M2<>"",M2,Z2) -> 720000 | AB2: =IF(L2<>"","Realizado","Previsto") -> Realizado | AD2: 8079999.9 | AI2: CUSTO CASA E CRONOGRAMA PAGAMEN | AJ2: =IF(Q2<>"",Q2,IF(K2<>"",K2,"")) -> 46080 | AK2: =IF(K2<>"","Sim","") -> Sim | AL2: =IF(A2="","",TEXT(A2,"000000")&"-"&IF(C2="Entrada","CR","DB")) -> 000001-CR | AM2: =IF(A2="","",LEFT(IF(H2<>"",H2,G2)&" | "&G2&" | "&S2,60)) -> FM SOLUÇÕES EM BEBIDAS | MEDIÇÃO CONTRATUAL | Entrada | MEDI
A3: 2 | B3: SÃO FRANCISCO DE PAULA - RS | C3: Saída | D3: DESPESAS ACESSÓRIAS | E3: DESPESAS ACESSÓRIAS | F3: DESPESAS ACESSÓRIAS | G3: CAUÇÃO | K3: 46092 | Q3: =IF(K3="","",K3) -> 46092 | R3: DESPESAS ACESSÓRIAS | S3: Saída | DESPESAS ACESSÓRIAS | T3: Saída | DESPESAS ACESSÓRIAS | DESPESAS ACESSÓRIAS | V3: 270 | W3: Q1 | X3: 46090 | Y3: 46101 | Z3: 64000 | AA3: =IF(M3<>"",M3,Z3) -> 64000 | AB3: =IF(L3<>"","Realizado","Previsto") -> Previsto | AC3: 1 | AD3: 64000 | AF3: mês | AG3: 64000 | AI3: CUSTO CASA E CRONOGRAMA PAGAMEN | AJ3: =IF(Q3<>"",Q3,IF(K3<>"",K3,"")) -> 46092 | AK3: =IF(K3<>"","Sim","") -> Sim | AL3: =IF(A3="","",TEXT(A3,"000000")&"-"&IF(C3="Entrada","CR","DB")) -> 000002-DB | AM3: =IF(A3="","",LEFT(IF(H3<>"",H3,G3)&" | "&G3&" | "&S3,60)) -> CAUÇÃO | CAUÇÃO | Saída | DESPESAS ACESSÓRIAS
A4: 3 | B4: SÃO FRANCISCO DE PAULA - RS | C4: Saída | D4: DESPESAS ACESSÓRIAS | E4: DESPESAS ACESSÓRIAS | F4: DESPESAS ACESSÓRIAS | G4: LOGISTICA GESTÃO VISITA À OBRA | K4: 46090 | Q4: =IF(K4="","",K4) -> 46090 | R4: DESPESAS ACESSÓRIAS | S4: Saída | DESPESAS ACESSÓRIAS | T4: Saída | DESPESAS ACESSÓRIAS | DESPESAS ACESSÓRIAS | V4: 271 | W4: Q1 | X4: 46090 | Y4: 46101 | Z4: 16000 | AA4: =IF(M4<>"",M4,Z4) -> 16000 | AB4: =IF(L4<>"","Realizado","Previsto") -> Previsto | AC4: 0.4 | AD4: 40000 | AF4: mês | AG4: 10000 | AI4: CUSTO CASA E CRONOGRAMA PAGAMEN | AJ4: =IF(Q4<>"",Q4,IF(K4<>"",K4,"")) -> 46090 | AK4: =IF(K4<>"","Sim","") -> Sim | AL4: =IF(A4="","",TEXT(A4,"000000")&"-"&IF(C4="Entrada","CR","DB")) -> 000003-DB | AM4: =IF(A4="","",LEFT(IF(H4<>"",H4,G4)&" | "&G4&" | "&S4,60)) -> LOGISTICA GESTÃO VISITA À OBRA | LOGISTICA GESTÃO VISITA À O
A5: 4 | B5: SÃO FRANCISCO DE PAULA - RS | C5: Saída | D5: DESPESAS ACESSÓRIAS | E5: DESPESAS ACESSÓRIAS | F5: DESPESAS ACESSÓRIAS | G5: SEGURO | K5: 46090 | Q5: =IF(K5="","",K5) -> 46090 | R5: DESPESAS ACESSÓRIAS | S5: Saída | DESPESAS ACESSÓRIAS | T5: Saída | DESPESAS ACESSÓRIAS | DESPESAS ACESSÓRIAS | V5: 269 | W5: Q1 | X5: 46090 | Y5: 46101 | Z5: 16000 | AA5: =IF(M5<>"",M5,Z5) -> 16000 | AB5: =IF(L5<>"","Realizado","Previsto") -> Previsto | AC5: 1 | AD5: 16000 | AF5: mês | AG5: 16000 | AI5: CUSTO CASA E CRONOGRAMA PAGAMEN | AJ5: =IF(Q5<>"",Q5,IF(K5<>"",K5,"")) -> 46090 | AK5: =IF(K5<>"","Sim","") -> Sim | AL5: =IF(A5="","",TEXT(A5,"000000")&"-"&IF(C5="Entrada","CR","DB")) -> 000004-DB | AM5: =IF(A5="","",LEFT(IF(H5<>"",H5,G5)&" | "&G5&" | "&S5,60)) -> SEGURO | SEGURO | Saída | DESPESAS ACESSÓRIAS
A6: 5 | B6: SÃO FRANCISCO DE PAULA - RS | C6: Saída | D6: GESTÃO LOCAL | E6: GESTÃO LOCAL | F6: MATERIAL | G6: Bebedouro | K6: 46092 | Q6: =IF(K6="","",K6) -> 46092 | R6: GESTÃO LOCAL | S6: Saída | GESTÃO LOCAL | T6: Saída | GESTÃO LOCAL | MATERIAL | V6: 257 | W6: Q1 | X6: 46090 | Y6: 46101 | Z6: 2500 | AA6: =IF(M6<>"",M6,Z6) -> 2500 | AB6: =IF(L6<>"","Realizado","Previsto") -> Previsto | AC6: 1 | AD6: 2500 | AF6: unidade | AG6: 2500 | AH6: C origem: MATERIAL | AI6: CUSTO CASA E CRONOGRAMA PAGAMEN | AJ6: =IF(Q6<>"",Q6,IF(K6<>"",K6,"")) -> 46092 | AK6: =IF(K6<>"","Sim","") -> Sim | AL6: =IF(A6="","",TEXT(A6,"000000")&"-"&IF(C6="Entrada","CR","DB")) -> 000005-DB | AM6: =IF(A6="","",LEFT(IF(H6<>"",H6,G6)&" | "&G6&" | "&S6,60)) -> Bebedouro | Bebedouro | Saída | GESTÃO LOCAL
A7: 6 | B7: SÃO FRANCISCO DE PAULA - RS | C7: Saída | D7: GESTÃO LOCAL | E7: GESTÃO LOCAL | F7: MATERIAL | G7: Placa da obra | K7: 46092 | Q7: =IF(K7="","",K7) -> 46092 | R7: GESTÃO LOCAL | S7: Saída | GESTÃO LOCAL | T7: Saída | GESTÃO LOCAL | MATERIAL | V7: 256 | W7: Q1 | X7: 46090 | Y7: 46101 | Z7: 2000 | AA7: =IF(M7<>"",M7,Z7) -> 2000 | AB7: =IF(L7<>"","Realizado","Previsto") -> Previsto | AC7: 1 | AD7: 2000 | AF7: unidade | AG7: 2000 | AH7: C origem: MATERIAL | AI7: CUSTO CASA E CRONOGRAMA PAGAMEN | AJ7: =IF(Q7<>"",Q7,IF(K7<>"",K7,"")) -> 46092 | AK7: =IF(K7<>"","Sim","") -> Sim | AL7: =IF(A7="","",TEXT(A7,"000000")&"-"&IF(C7="Entrada","CR","DB")) -> 000006-DB | AM7: =IF(A7="","",LEFT(IF(H7<>"",H7,G7)&" | "&G7&" | "&S7,60)) -> Placa da obra | Placa da obra | Saída | GESTÃO LOCAL
A8: 7 | B8: SÃO FRANCISCO DE PAULA - RS | C8: Saída | D8: GESTÃO LOCAL | E8: GESTÃO LOCAL | F8: ADMINISTRAÇAO | G8: TOPOGRAFO | K8: 46101 | Q8: =IF(K8="","",K8) -> 46101 | R8: GESTÃO LOCAL | S8: Saída | GESTÃO LOCAL | T8: Saída | GESTÃO LOCAL | ADMINISTRAÇAO | V8: 260 | W8: Q1 | X8: 46090 | Y8: 46101 | Z8: 6000 | AA8: =IF(M8<>"",M8,Z8) -> 6000 | AB8: =IF(L8<>"","Realizado","Previsto") -> Previsto | AC8: 1 | AD8: 6000 | AF8: mês | AG8: 2000 | AH8: C origem: ADMINISTRAÇAO | AI8: CUSTO CASA E CRONOGRAMA PAGAMEN | AJ8: =IF(Q8<>"",Q8,IF(K8<>"",K8,"")) -> 46101 | AK8: =IF(K8<>"","Sim","") -> Sim | AL8: =IF(A8="","",TEXT(A8,"000000")&"-"&IF(C8="Entrada","CR","DB")) -> 000007-DB | AM8: =IF(A8="","",LEFT(IF(H8<>"",H8,G8)&" | "&G8&" | "&S8,60)) -> TOPOGRAFO | TOPOGRAFO | Saída | GESTÃO LOCAL
A9: 8 | B9: SÃO FRANCISCO DE PAULA - RS | C9: Saída | D9: GESTÃO LOCAL | E9: GESTÃO LOCAL | F9: LOCAÇAO | G9: mobilização / desmobilzaçao containers | K9: 46101 | Q9: =IF(K9="","",K9) -> 46101 | R9: GESTÃO LOCAL | S9: Saída | GESTÃO LOCAL | T9: Saída | GESTÃO LOCAL | LOCAÇAO | V9: 253 | W9: Q1 | X9: 46090 | Y9: 46101 | Z9: 6100 | AA9: =IF(M9<>"",M9,Z9) -> 6100 | AB9: =IF(L9<>"","Realizado","Previsto") -> Previsto | AC9: 0.5 | AD9: 12200 | AF9: mês | AG9: 6100 | AH9: C origem: LOCAÇAO | AI9: CUSTO CASA E CRONOGRAMA PAGAMEN | AJ9: =IF(Q9<>"",Q9,IF(K9<>"",K9,"")) -> 46101 | AK9: =IF(K9<>"","Sim","") -> Sim | AL9: =IF(A9="","",TEXT(A9,"000000")&"-"&IF(C9="Entrada","CR","DB")) -> 000008-DB | AM9: =IF(A9="","",LEFT(IF(H9<>"",H9,G9)&" | "&G9&" | "&S9,60)) -> mobilização / desmobilzaçao containers | mobilização / desmo
A10: 9 | B10: SÃO FRANCISCO DE PAULA - RS | C10: Saída | D10: PAREDES (102,5m² de área interna e externa) (44,38² de Laje) | E10: PAREDES COM CONCRETO | F10: FABRICA | G10: contrato industrializaçao paredes | K10: 46101 | Q10: =IF(K10="","",K10) -> 46101 | R10: PAREDES (102,5m² de área interna e externa) (44,38² de Laje) | S10: Saída | PAREDES (102,5m² de área interna e externa) (44,38² de Laje) | T10: Saída | PAREDES COM CONCRETO | FABRICA | U10: 20 | V10: 48 | W10: Q1 | X10: 46090 | Y10: 46101 | Z10: 96000 | AA10: =IF(M10<>"",M10,Z10) -> 96000 | AB10: =IF(L10<>"","Realizado","Previsto") -> Previsto | AC10: 0.3 | AD10: 320000 | AE10: 20 | AF10: unidade | AG10: 16000 | AH10: B origem: PAREDES COM CONCRETO | C origem: FABRICA | AI10: CUSTO CASA E CRONOGRAMA PAGAMEN | AJ10: =IF(Q10<>"",Q10,IF(K10<>"",K10,"")) -> 46101 | AK10: =IF(K10<>"","Sim","") -> Sim | AL10: =IF(A10="","",TEXT(A10,"000000")&"-"&IF(C10="Entrada","CR","DB")) -> 000009-DB | AM10: =IF(A10="","",LEFT(IF(H10<>"",H10,G10)&" | "&G10&" | "&S10,60)) -> contrato industrializaçao paredes | contrato industrializaça
A11: 10 | B11: SÃO FRANCISCO DE PAULA - RS | C11: Saída | D11: PAREDES (102,5m² de área interna e externa) (44,38² de Laje) | E11: PAREDES COM CONCRETO | F11: FABRICA | G11: contrato industrializaçao paredes | K11: 46101 | Q11: =IF(K11="","",K11) -> 46101 | R11: PAREDES (102,5m² de área interna e externa) (44,38² de Laje) | S11: Saída | PAREDES (102,5m² de área interna e externa) (44,38² de Laje) | T11: Saída | PAREDES COM CONCRETO | FABRICA | U11: 20 | V11: 49 | W11: Q1 | X11: 46090 | Y11: 46101 | Z11: 96000 | AA11: =IF(M11<>"",M11,Z11) -> 96000 | AB11: =IF(L11<>"","Realizado","Previsto") -> Previsto | AC11: 0.3 | AD11: 320000 | AE11: 20 | AF11: unidade | AG11: 16000 | AH11: B origem: PAREDES COM CONCRETO | C origem: FABRICA | AI11: CUSTO CASA E CRONOGRAMA PAGAMEN | AJ11: =IF(Q11<>"",Q11,IF(K11<>"",K11,"")) -> 46101 | AK11: =IF(K11<>"","Sim","") -> Sim | AL11: =IF(A11="","",TEXT(A11,"000000")&"-"&IF(C11="Entrada","CR","DB")) -> 000010-DB | AM11: =IF(A11="","",LEFT(IF(H11<>"",H11,G11)&" | "&G11&" | "&S11,60)) -> contrato industrializaçao paredes | contrato industrializaça
A12: 11 | B12: SÃO FRANCISCO DE PAULA - RS | C12: Saída | D12: PAREDES (102,5m² de área interna e externa) (44,38² de Laje) | E12: PAREDES COM CONCRETO | F12: FABRICA | G12: contrato industrializaçao paredes | K12: 46101 | Q12: =IF(K12="","",K12) -> 46101 | R12: PAREDES (102,5m² de área interna e externa) (44,38² de Laje) | S12: Saída | PAREDES (102,5m² de área interna e externa) (44,38² de Laje) | T12: Saída | PAREDES COM CONCRETO | FABRICA | U12: 24 | V12: 50 | W12: Q1 | X12: 46090 | Y12: 46101 | Z12: 115200 | AA12: =IF(M12<>"",M12,Z12) -> 115200 | AB12: =IF(L12<>"","Realizado","Previsto") -> Previsto | AC12: 0.3 | AD12: 384000 | AE12: 24 | AF12: unidade | AG12: 16000 | AH12: B origem: PAREDES COM CONCRETO | C origem: FABRICA | AI12: CUSTO CASA E CRONOGRAMA PAGAMEN | AJ12: =IF(Q12<>"",Q12,IF(K12<>"",K12,"")) -> 46101 | AK12: =IF(K12<>"","Sim","") -> Sim | AL12: =IF(A12="","",TEXT(A12,"000000")&"-"&IF(C12="Entrada","CR","DB")) -> 000011-DB | AM12: =IF(A12="","",LEFT(IF(H12<>"",H12,G12)&" | "&G12&" | "&S12,60)) -> contrato industrializaçao paredes | contrato industrializaça
A13: 12 | B13: SÃO FRANCISCO DE PAULA - RS | C13: Saída | D13: RADIER - 44,38 M² | E13: RADIER | F13: MAO DE OBRA | G13: Mao de obra Terceirizada Radier | K13: 46101 | Q13: =IF(K13="","",K13) -> 46101 | R13: RADIER - 44,38 M² | S13: Saída | RADIER - 44,38 M² | T13: Saída | RADIER | MAO DE OBRA | V13: 43 | W13: Q1 | X13: 46090 | Y13: 46101 | Z13: 24750 | AA13: =IF(M13<>"",M13,Z13) -> 24750 | AB13: =IF(L13<>"","Realizado","Previsto") -> Previsto | AC13: 0.19335938 | AD13: 128000 | AE13: 64 | AF13: vb | AG13: 2000 | AH13: B origem: RADIER | C origem: MAO DE OBRA | AI13: CUSTO CASA E CRONOGRAMA PAGAMEN | AJ13: =IF(Q13<>"",Q13,IF(K13<>"",K13,"")) -> 46101 | AK13: =IF(K13<>"","Sim","") -> Sim | AL13: =IF(A13="","",TEXT(A13,"000000")&"-"&IF(C13="Entrada","CR","DB")) -> 000012-DB | AM13: =IF(A13="","",LEFT(IF(H13<>"",H13,G13)&" | "&G13&" | "&S13,60)) -> Mao de obra Terceirizada Radier | Mao de obra Terceirizada R
A14: 13 | B14: SÃO FRANCISCO DE PAULA - RS | C14: Saída | D14: RADIER - 44,38 M² | E14: RADIER | F14: MADEIRA | G14: ripas de 5cm x 2,7m de 25mm | K14: 46101 | Q14: =IF(K14="","",K14) -> 46101 | R14: RADIER - 44,38 M² | S14: Saída | RADIER - 44,38 M² | T14: Saída | RADIER | MADEIRA | V14: 44 | W14: Q1 | X14: 46090 | Y14: 46101 | Z14: 1689.6 | AA14: =IF(M14<>"",M14,Z14) -> 1689.6 | AB14: =IF(L14<>"","Realizado","Previsto") -> Previsto | AC14: 0.4 | AD14: 4224 | AE14: 704 | AF14: pç | AG14: 6 | AH14: B origem: RADIER | C origem: MADEIRA | AI14: CUSTO CASA E CRONOGRAMA PAGAMEN | AJ14: =IF(Q14<>"",Q14,IF(K14<>"",K14,"")) -> 46101 | AK14: =IF(K14<>"","Sim","") -> Sim | AL14: =IF(A14="","",TEXT(A14,"000000")&"-"&IF(C14="Entrada","CR","DB")) -> 000013-DB | AM14: =IF(A14="","",LEFT(IF(H14<>"",H14,G14)&" | "&G14&" | "&S14,60)) -> ripas de 5cm x 2,7m de 25mm | ripas de 5cm x 2,7m de 25mm |
A15: 14 | B15: SÃO FRANCISCO DE PAULA - RS | C15: Saída | D15: SERVIÇOS | E15: SERVIÇOS | F15: SERVIÇOS | G15: TOTALIZADOR CUSTO GLOBAIS OBRAS - MENSAL | K15: 46101 | Q15: =IF(K15="","",K15) -> 46101 | R15: SERVIÇOS | S15: Saída | SERVIÇOS | T15: Saída | SERVIÇOS | SERVIÇOS | V15: 267 | W15: Q1 | X15: 46090 | Y15: 46101 | Z15: 350239.6 | AA15: =IF(M15<>"",M15,Z15) -> 350239.6 | AB15: =IF(L15<>"","Realizado","Previsto") -> Previsto | AD15: 5780911.4 | AF15: mês | AI15: CUSTO CASA E CRONOGRAMA PAGAMEN | AJ15: =IF(Q15<>"",Q15,IF(K15<>"",K15,"")) -> 46101 | AK15: =IF(K15<>"","Sim","") -> Sim | AL15: =IF(A15="","",TEXT(A15,"000000")&"-"&IF(C15="Entrada","CR","DB")) -> 000014-DB | AM15: =IF(A15="","",LEFT(IF(H15<>"",H15,G15)&" | "&G15&" | "&S15,60)) -> TOTALIZADOR CUSTO GLOBAIS OBRAS - MENSAL | TOTALIZADOR CUSTO
A16: 15 | B16: SÃO FRANCISCO DE PAULA - RS | C16: Saída | D16: CAPITAL DE GIRO | E16: CAPITAL DE GIRO | F16: EMPRÉSTIMOS / CAPITAL DE GIRO | G16: ITAU | K16: 46115 | Q16: =IF(K16="","",K16) -> 46115 | R16: CAPITAL DE GIRO | S16: Saída | CAPITAL DE GIRO | T16: Saída | CAPITAL DE GIRO | EMPRÉSTIMOS / CAPITAL DE GIRO | V16: 273 | W16: Q2 | X16: 46104 | Y16: 46115 | Z16: 19943.37 | AA16: =IF(M16<>"",M16,Z16) -> 19943.37 | AB16: =IF(L16<>"","Realizado","Previsto") -> Previsto | AD16: 307830.11 | AG16: 248 | AH16: C origem: 248000 | AI16: CUSTO CASA E CRONOGRAMA PAGAMEN | AJ16: =IF(Q16<>"",Q16,IF(K16<>"",K16,"")) -> 46115 | AK16: =IF(K16<>"","Sim","") -> Sim | AL16: =IF(A16="","",TEXT(A16,"000000")&"-"&IF(C16="Entrada","CR","DB")) -> 000015-DB | AM16: =IF(A16="","",LEFT(IF(H16<>"",H16,G16)&" | "&G16&" | "&S16,60)) -> ITAU | ITAU | Saída | CAPITAL DE GIRO
A17: 16 | B17: SÃO FRANCISCO DE PAULA - RS | C17: Saída | D17: ESPERAS DE ESGOTO RADIER | E17: ESPERAS DE ESGOTO RADIER | F17: Tubos e conexoes | G17: Anel de vedação esg 100 mm | K17: 46115 | Q17: =IF(K17="","",K17) -> 46115 | R17: ESPERAS DE ESGOTO RADIER | S17: Saída | ESPERAS DE ESGOTO RADIER | T17: Saída | ESPERAS DE ESGOTO RADIER | Tubos e conexoes | V17: 21 | W17: Q2 | X17: 46104 | Y17: 46115 | Z17: 47.872 | AA17: =IF(M17<>"",M17,Z17) -> 47.872 | AB17: =IF(L17<>"","Realizado","Previsto") -> Previsto | AC17: 0.34 | AD17: 140.8 | AE17: 64 | AF17: unidade | AG17: 2.2 | AH17: B origem: ESPERAS DE ESGOTO RADIER | C origem: Tubos e conexoes | AI17: CUSTO CASA E CRONOGRAMA PAGAMEN | AJ17: =IF(Q17<>"",Q17,IF(K17<>"",K17,"")) -> 46115 | AK17: =IF(K17<>"","Sim","") -> Sim | AL17: =IF(A17="","",TEXT(A17,"000000")&"-"&IF(C17="Entrada","CR","DB")) -> 000016-DB | AM17: =IF(A17="","",LEFT(IF(H17<>"",H17,G17)&" | "&G17&" | "&S17,60)) -> Anel de vedação esg 100 mm | Anel de vedação esg 100 mm | Sa
A18: 17 | B18: SÃO FRANCISCO DE PAULA - RS | C18: Saída | D18: ESPERAS DE ESGOTO RADIER | E18: ESPERAS DE ESGOTO RADIER | F18: Tubos e conexoes | G18: Caixa Sifonada com grelha quadrada PVC DN 150x150x50 com junta soldável para ramal de esgoto sanitário | K18: 46115 | Q18: =IF(K18="","",K18) -> 46115 | R18: ESPERAS DE ESGOTO RADIER | S18: Saída | ESPERAS DE ESGOTO RADIER | T18: Saída | ESPERAS DE ESGOTO RADIER | Tubos e conexoes | V18: 19 | W18: Q2 | X18: 46104 | Y18: 46115 | Z18: 696.32 | AA18: =IF(M18<>"",M18,Z18) -> 696.32 | AB18: =IF(L18<>"","Realizado","Previsto") -> Previsto | AC18: 0.34 | AD18: 2048 | AE18: 64 | AF18: unidade | AG18: 32 | AH18: B origem: ESPERAS DE ESGOTO RADIER | C origem: Tubos e conexoes | AI18: CUSTO CASA E CRONOGRAMA PAGAMEN | AJ18: =IF(Q18<>"",Q18,IF(K18<>"",K18,"")) -> 46115 | AK18: =IF(K18<>"","Sim","") -> Sim | AL18: =IF(A18="","",TEXT(A18,"000000")&"-"&IF(C18="Entrada","CR","DB")) -> 000017-DB | AM18: =IF(A18="","",LEFT(IF(H18<>"",H18,G18)&" | "&G18&" | "&S18,60)) -> Caixa Sifonada com grelha quadrada PVC DN 150x150x50 com jun
A19: 18 | B19: SÃO FRANCISCO DE PAULA - RS | C19: Saída | D19: ESPERAS DE ESGOTO RADIER | E19: ESPERAS DE ESGOTO RADIER | F19: Tubos e conexoes | G19: Cola de cano PVC 175g | K19: 46115 | Q19: =IF(K19="","",K19) -> 46115 | R19: ESPERAS DE ESGOTO RADIER | S19: Saída | ESPERAS DE ESGOTO RADIER | T19: Saída | ESPERAS DE ESGOTO RADIER | Tubos e conexoes | V19: 24 | W19: Q2 | X19: 46104 | Y19: 46115 | Z19: 304.4224 | AA19: =IF(M19<>"",M19,Z19) -> 304.4224 | AB19: =IF(L19<>"","Realizado","Previsto") -> Previsto | AC19: 0.34 | AD19: 895.36 | AE19: 64 | AF19: unidade | AG19: 13.99 | AH19: B origem: ESPERAS DE ESGOTO RADIER | C origem: Tubos e conexoes | AI19: CUSTO CASA E CRONOGRAMA PAGAMEN | AJ19: =IF(Q19<>"",Q19,IF(K19<>"",K19,"")) -> 46115 | AK19: =IF(K19<>"","Sim","") -> Sim | AL19: =IF(A19="","",TEXT(A19,"000000")&"-"&IF(C19="Entrada","CR","DB")) -> 000018-DB | AM19: =IF(A19="","",LEFT(IF(H19<>"",H19,G19)&" | "&G19&" | "&S19,60)) -> Cola de cano PVC 175g | Cola de cano PVC 175g | Saída | ESPE
A20: 19 | B20: SÃO FRANCISCO DE PAULA - RS | C20: Saída | D20: ESPERAS DE ESGOTO RADIER | E20: ESPERAS DE ESGOTO RADIER | F20: Tubos e conexoes | G20: Joelho 45º PVC DN 40mm branco rígido para esgoto sanitário predial | K20: 46115 | Q20: =IF(K20="","",K20) -> 46115 | R20: ESPERAS DE ESGOTO RADIER | S20: Saída | ESPERAS DE ESGOTO RADIER | T20: Saída | ESPERAS DE ESGOTO RADIER | Tubos e conexoes | V20: 13 | W20: Q2 | X20: 46104 | Y20: 46115 | Z20: 30.464 | AA20: =IF(M20<>"",M20,Z20) -> 30.464 | AB20: =IF(L20<>"","Realizado","Previsto") -> Previsto | AC20: 0.34 | AD20: 89.6 | AE20: 64 | AF20: unidade | AG20: 1.4 | AH20: B origem: ESPERAS DE ESGOTO RADIER | C origem: Tubos e conexoes | AI20: CUSTO CASA E CRONOGRAMA PAGAMEN | AJ20: =IF(Q20<>"",Q20,IF(K20<>"",K20,"")) -> 46115 | AK20: =IF(K20<>"","Sim","") -> Sim | AL20: =IF(A20="","",TEXT(A20,"000000")&"-"&IF(C20="Entrada","CR","DB")) -> 000019-DB | AM20: =IF(A20="","",LEFT(IF(H20<>"",H20,G20)&" | "&G20&" | "&S20,60)) -> Joelho 45º PVC DN 40mm branco rígido para esgoto sanitário p
A21: 20 | B21: SÃO FRANCISCO DE PAULA - RS | C21: Saída | D21: ESPERAS DE ESGOTO RADIER | E21: ESPERAS DE ESGOTO RADIER | F21: Tubos e conexoes | G21: Joelho 45º PVC DN 50mm branco rígido para esgoto sanitário predial | K21: 46115 | Q21: =IF(K21="","",K21) -> 46115 | R21: ESPERAS DE ESGOTO RADIER | S21: Saída | ESPERAS DE ESGOTO RADIER | T21: Saída | ESPERAS DE ESGOTO RADIER | Tubos e conexoes | V21: 15 | W21: Q2 | X21: 46104 | Y21: 46115 | Z21: 130.56 | AA21: =IF(M21<>"",M21,Z21) -> 130.56 | AB21: =IF(L21<>"","Realizado","Previsto") -> Previsto | AC21: 0.34 | AD21: 384 | AE21: 64 | AF21: unidade | AG21: 6 | AH21: B origem: ESPERAS DE ESGOTO RADIER | C origem: Tubos e conexoes | AI21: CUSTO CASA E CRONOGRAMA PAGAMEN | AJ21: =IF(Q21<>"",Q21,IF(K21<>"",K21,"")) -> 46115 | AK21: =IF(K21<>"","Sim","") -> Sim | AL21: =IF(A21="","",TEXT(A21,"000000")&"-"&IF(C21="Entrada","CR","DB")) -> 000020-DB | AM21: =IF(A21="","",LEFT(IF(H21<>"",H21,G21)&" | "&G21&" | "&S21,60)) -> Joelho 45º PVC DN 50mm branco rígido para esgoto sanitário p
A22: 21 | B22: SÃO FRANCISCO DE PAULA - RS | C22: Saída | D22: ESPERAS DE ESGOTO RADIER | E22: ESPERAS DE ESGOTO RADIER | F22: Tubos e conexoes | G22: Joelho 90º PVC DN 100mm branco rígido para esgoto sanitário predial | K22: 46115 | Q22: =IF(K22="","",K22) -> 46115 | R22: ESPERAS DE ESGOTO RADIER | S22: Saída | ESPERAS DE ESGOTO RADIER | T22: Saída | ESPERAS DE ESGOTO RADIER | Tubos e conexoes | V22: 11 | W22: Q2 | X22: 46104 | Y22: 46115 | Z22: 304.4224 | AA22: =IF(M22<>"",M22,Z22) -> 304.4224 | AB22: =IF(L22<>"","Realizado","Previsto") -> Previsto | AC22: 0.34 | AD22: 895.36 | AE22: 64 | AF22: unidade | AG22: 13.99 | AH22: B origem: ESPERAS DE ESGOTO RADIER | C origem: Tubos e conexoes | AI22: CUSTO CASA E CRONOGRAMA PAGAMEN | AJ22: =IF(Q22<>"",Q22,IF(K22<>"",K22,"")) -> 46115 | AK22: =IF(K22<>"","Sim","") -> Sim | AL22: =IF(A22="","",TEXT(A22,"000000")&"-"&IF(C22="Entrada","CR","DB")) -> 000021-DB | AM22: =IF(A22="","",LEFT(IF(H22<>"",H22,G22)&" | "&G22&" | "&S22,60)) -> Joelho 90º PVC DN 100mm branco rígido para esgoto sanitário
A23: 22 | B23: SÃO FRANCISCO DE PAULA - RS | C23: Saída | D23: ESPERAS DE ESGOTO RADIER | E23: ESPERAS DE ESGOTO RADIER | F23: Tubos e conexoes | G23: Joelho 90º PVC DN 40mm branco rígido para esgoto sanitário predial | K23: 46115 | Q23: =IF(K23="","",K23) -> 46115 | R23: ESPERAS DE ESGOTO RADIER | S23: Saída | ESPERAS DE ESGOTO RADIER | T23: Saída | ESPERAS DE ESGOTO RADIER | Tubos e conexoes | V23: 12 | W23: Q2 | X23: 46104 | Y23: 46115 | Z23: 134.4768 | AA23: =IF(M23<>"",M23,Z23) -> 134.4768 | AB23: =IF(L23<>"","Realizado","Previsto") -> Previsto | AC23: 0.34 | AD23: 395.52 | AE23: 128 | AF23: unidade | AG23: 3.09 | AH23: B origem: ESPERAS DE ESGOTO RADIER | C origem: Tubos e conexoes | AI23: CUSTO CASA E CRONOGRAMA PAGAMEN | AJ23: =IF(Q23<>"",Q23,IF(K23<>"",K23,"")) -> 46115 | AK23: =IF(K23<>"","Sim","") -> Sim | AL23: =IF(A23="","",TEXT(A23,"000000")&"-"&IF(C23="Entrada","CR","DB")) -> 000022-DB | AM23: =IF(A23="","",LEFT(IF(H23<>"",H23,G23)&" | "&G23&" | "&S23,60)) -> Joelho 90º PVC DN 40mm branco rígido para esgoto sanitário p
A24: 23 | B24: SÃO FRANCISCO DE PAULA - RS | C24: Saída | D24: ESPERAS DE ESGOTO RADIER | E24: ESPERAS DE ESGOTO RADIER | F24: Tubos e conexoes | G24: Joelho 90º PVC DN 50mm branco junta elástica para esgoto sanitário | K24: 46115 | Q24: =IF(K24="","",K24) -> 46115 | R24: ESPERAS DE ESGOTO RADIER | S24: Saída | ESPERAS DE ESGOTO RADIER | T24: Saída | ESPERAS DE ESGOTO RADIER | Tubos e conexoes | V24: 14 | W24: Q2 | X24: 46104 | Y24: 46115 | Z24: 746.8032 | AA24: =IF(M24<>"",M24,Z24) -> 746.8032 | AB24: =IF(L24<>"","Realizado","Previsto") -> Previsto | AC24: 0.34 | AD24: 2196.48 | AE24: 384 | AF24: unidade | AG24: 5.72 | AH24: B origem: ESPERAS DE ESGOTO RADIER | C origem: Tubos e conexoes | AI24: CUSTO CASA E CRONOGRAMA PAGAMEN | AJ24: =IF(Q24<>"",Q24,IF(K24<>"",K24,"")) -> 46115 | AK24: =IF(K24<>"","Sim","") -> Sim | AL24: =IF(A24="","",TEXT(A24,"000000")&"-"&IF(C24="Entrada","CR","DB")) -> 000023-DB | AM24: =IF(A24="","",LEFT(IF(H24<>"",H24,G24)&" | "&G24&" | "&S24,60)) -> Joelho 90º PVC DN 50mm branco junta elástica para esgoto san
A25: 24 | B25: SÃO FRANCISCO DE PAULA - RS | C25: Saída | D25: ESPERAS DE ESGOTO RADIER | E25: ESPERAS DE ESGOTO RADIER | F25: Tubos e conexoes | G25: Joelho 90º marrom DN 25mm soldável para água fria | K25: 46115 | Q25: =IF(K25="","",K25) -> 46115 | R25: ESPERAS DE ESGOTO RADIER | S25: Saída | ESPERAS DE ESGOTO RADIER | T25: Saída | ESPERAS DE ESGOTO RADIER | Tubos e conexoes | V25: 25 | W25: Q2 | X25: 46104 | Y25: 46115 | Z25: 41.344 | AA25: =IF(M25<>"",M25,Z25) -> 41.344 | AB25: =IF(L25<>"","Realizado","Previsto") -> Previsto | AC25: 0.34 | AD25: 121.6 | AE25: 128 | AF25: unidade | AG25: 0.95 | AH25: B origem: ESPERAS DE ESGOTO RADIER | C origem: Tubos e conexoes | AI25: CUSTO CASA E CRONOGRAMA PAGAMEN | AJ25: =IF(Q25<>"",Q25,IF(K25<>"",K25,"")) -> 46115 | AK25: =IF(K25<>"","Sim","") -> Sim | AL25: =IF(A25="","",TEXT(A25,"000000")&"-"&IF(C25="Entrada","CR","DB")) -> 000024-DB | AM25: =IF(A25="","",LEFT(IF(H25<>"",H25,G25)&" | "&G25&" | "&S25,60)) -> Joelho 90º marrom DN 25mm soldável para água fria | Joelho 9
A26: 25 | B26: SÃO FRANCISCO DE PAULA - RS | C26: Saída | D26: ESPERAS DE ESGOTO RADIER | E26: ESPERAS DE ESGOTO RADIER | F26: Tubos e conexoes | G26: Junção de Redução invertica PVC DN 100x50mm branco rígido para esgoto sanitário predial | K26: 46115 | Q26: =IF(K26="","",K26) -> 46115 | R26: ESPERAS DE ESGOTO RADIER | S26: Saída | ESPERAS DE ESGOTO RADIER | T26: Saída | ESPERAS DE ESGOTO RADIER | Tubos e conexoes | V26: 17 | W26: Q2 | X26: 46104 | Y26: 46115 | Z26: 469.1456 | AA26: =IF(M26<>"",M26,Z26) -> 469.1456 | AB26: =IF(L26<>"","Realizado","Previsto") -> Previsto | AC26: 0.34 | AD26: 1379.84 | AE26: 64 | AF26: unidade | AG26: 21.56 | AH26: B origem: ESPERAS DE ESGOTO RADIER | C origem: Tubos e conexoes | AI26: CUSTO CASA E CRONOGRAMA PAGAMEN | AJ26: =IF(Q26<>"",Q26,IF(K26<>"",K26,"")) -> 46115 | AK26: =IF(K26<>"","Sim","") -> Sim | AL26: =IF(A26="","",TEXT(A26,"000000")&"-"&IF(C26="Entrada","CR","DB")) -> 000025-DB | AM26: =IF(A26="","",LEFT(IF(H26<>"",H26,G26)&" | "&G26&" | "&S26,60)) -> Junção de Redução invertica PVC DN 100x50mm branco rígido pa
A27: 26 | B27: SÃO FRANCISCO DE PAULA - RS | C27: Saída | D27: ESPERAS DE ESGOTO RADIER | E27: ESPERAS DE ESGOTO RADIER | F27: Tubos e conexoes | G27: Junção simples PVC DN 50x50mm branco rígido para esgoto sanitário predial | K27: 46115 | Q27: =IF(K27="","",K27) -> 46115 | R27: ESPERAS DE ESGOTO RADIER | S27: Saída | ESPERAS DE ESGOTO RADIER | T27: Saída | ESPERAS DE ESGOTO RADIER | Tubos e conexoes | V27: 16 | W27: Q2 | X27: 46104 | Y27: 46115 | Z27: 391.2448 | AA27: =IF(M27<>"",M27,Z27) -> 391.2448 | AB27: =IF(L27<>"","Realizado","Previsto") -> Previsto | AC27: 0.34 | AD27: 1150.72 | AE27: 64 | AF27: unidade | AG27: 17.98 | AH27: B origem: ESPERAS DE ESGOTO RADIER | C origem: Tubos e conexoes | AI27: CUSTO CASA E CRONOGRAMA PAGAMEN | AJ27: =IF(Q27<>"",Q27,IF(K27<>"",K27,"")) -> 46115 | AK27: =IF(K27<>"","Sim","") -> Sim | AL27: =IF(A27="","",TEXT(A27,"000000")&"-"&IF(C27="Entrada","CR","DB")) -> 000026-DB | AM27: =IF(A27="","",LEFT(IF(H27<>"",H27,G27)&" | "&G27&" | "&S27,60)) -> Junção simples PVC DN 50x50mm branco rígido para esgoto sani
A28: 27 | B28: SÃO FRANCISCO DE PAULA - RS | C28: Saída | D28: ESPERAS DE ESGOTO RADIER | E28: ESPERAS DE ESGOTO RADIER | F28: Tubos e conexoes | G28: Lixa ferro p/cano pvc 100 | K28: 46115 | Q28: =IF(K28="","",K28) -> 46115 | R28: ESPERAS DE ESGOTO RADIER | S28: Saída | ESPERAS DE ESGOTO RADIER | T28: Saída | ESPERAS DE ESGOTO RADIER | Tubos e conexoes | V28: 22 | W28: Q2 | X28: 46104 | Y28: 46115 | Z28: 36.7744 | AA28: =IF(M28<>"",M28,Z28) -> 36.7744 | AB28: =IF(L28<>"","Realizado","Previsto") -> Previsto | AC28: 0.34 | AD28: 108.16 | AE28: 64 | AF28: unidade | AG28: 1.69 | AH28: B origem: ESPERAS DE ESGOTO RADIER | C origem: Tubos e conexoes | AI28: CUSTO CASA E CRONOGRAMA PAGAMEN | AJ28: =IF(Q28<>"",Q28,IF(K28<>"",K28,"")) -> 46115 | AK28: =IF(K28<>"","Sim","") -> Sim | AL28: =IF(A28="","",TEXT(A28,"000000")&"-"&IF(C28="Entrada","CR","DB")) -> 000027-DB | AM28: =IF(A28="","",LEFT(IF(H28<>"",H28,G28)&" | "&G28&" | "&S28,60)) -> Lixa ferro p/cano pvc 100 | Lixa ferro p/cano pvc 100 | Saíd
... A36: 35 | B36: SÃO FRANCISCO DE PAULA - RS | C36: Saída | D36: ESPERAS DE ESGOTO RADIER | E36: ESPERAS DE ESGOTO RADIER | F36: Tubos e conexoes | G36: Tubo PVC DN 75mm branco rígido para esgoto sanitário | K36: 46115 | Q36: =IF(K36="","",K36) -> 46115 | R36: ESPERAS DE ESGOTO RADIER | S36: Saída | ESPERAS DE ESGOTO RADIER | T36: Saída | ESPERAS DE ESGOTO RADIER | Tubos e conexoes | V36: 9 | W36: Q2 | X36: 46104 | Y36: 46115 | Z36: 82.40512 | AA36: =IF(M36<>"",M36,Z36) -> 82.40512 | AB36: =IF(L36<>"","Realizado","Previsto") -> Previsto | AC36: 0.34 | AD36: 242.368 | AE36: 22.4 | AF36: m | AG36: 10.82 | AH36: B origem: ESPERAS DE ESGOTO RADIER | C origem: Tubos e conexoes | AI36: CUSTO CASA E CRONOGRAMA PAGAMEN | AJ36: =IF(Q36<>"",Q36,IF(K36<>"",K36,"")) -> 46115 | AK36: =IF(K36<>"","Sim","") -> Sim | AL36: =IF(A36="","",TEXT(A36,"000000")&"-"&IF(C36="Entrada","CR","DB")) -> 000035-DB | AM36: =IF(A36="","",LEFT(IF(H36<>"",H36,G36)&" | "&G36&" | "&S36,60)) -> Tubo PVC DN 75mm branco rígido para esgoto sanitário | Tubo
A37: 36 | B37: SÃO FRANCISCO DE PAULA - RS | C37: Saída | D37: GESTÃO LOCAL | E37: GESTÃO LOCAL | F37: ADMINISTRAÇAO | G37: ALMOXARIFADO | K37: 46115 | Q37: =IF(K37="","",K37) -> 46115 | R37: GESTÃO LOCAL | S37: Saída | GESTÃO LOCAL | T37: Saída | GESTÃO LOCAL | ADMINISTRAÇAO | V37: 264 | W37: Q2 | X37: 46104 | Y37: 46115 | Z37: 7500 | AA37: =IF(M37<>"",M37,Z37) -> 7500 | AB37: =IF(L37<>"","Realizado","Previsto") -> Previsto | AC37: 0.25 | AD37: 30000 | AG37: 7500 | AH37: C origem: ADMINISTRAÇAO | AI37: CUSTO CASA E CRONOGRAMA PAGAMEN | AJ37: =IF(Q37<>"",Q37,IF(K37<>"",K37,"")) -> 46115 | AK37: =IF(K37<>"","Sim","") -> Sim | AL37: =IF(A37="","",TEXT(A37,"000000")&"-"&IF(C37="Entrada","CR","DB")) -> 000036-DB | AM37: =IF(A37="","",LEFT(IF(H37<>"",H37,G37)&" | "&G37&" | "&S37,60)) -> ALMOXARIFADO | ALMOXARIFADO | Saída | GESTÃO LOCAL
A38: 37 | B38: SÃO FRANCISCO DE PAULA - RS | C38: Saída | D38: GESTÃO LOCAL | E38: GESTÃO LOCAL | F38: ADMINISTRAÇAO | G38: Alojamento Arbnb (mestre, engenheiro. Tecnico) | K38: 46115 | Q38: =IF(K38="","",K38) -> 46115 | R38: GESTÃO LOCAL | S38: Saída | GESTÃO LOCAL | T38: Saída | GESTÃO LOCAL | ADMINISTRAÇAO | V38: 265 | W38: Q2 | X38: 46104 | Y38: 46115 | Z38: 3500 | AA38: =IF(M38<>"",M38,Z38) -> 3500 | AB38: =IF(L38<>"","Realizado","Previsto") -> Previsto | AC38: 0.25 | AD38: 14000 | AF38: mês | AG38: 3500 | AH38: C origem: ADMINISTRAÇAO | AI38: CUSTO CASA E CRONOGRAMA PAGAMEN | AJ38: =IF(Q38<>"",Q38,IF(K38<>"",K38,"")) -> 46115 | AK38: =IF(K38<>"","Sim","") -> Sim | AL38: =IF(A38="","",TEXT(A38,"000000")&"-"&IF(C38="Entrada","CR","DB")) -> 000037-DB | AM38: =IF(A38="","",LEFT(IF(H38<>"",H38,G38)&" | "&G38&" | "&S38,60)) -> Alojamento Arbnb (mestre, engenheiro. Tecnico) | Alojamento
A39: 38 | B39: SÃO FRANCISCO DE PAULA - RS | C39: Saída | D39: GESTÃO LOCAL | E39: GESTÃO LOCAL | F39: LOCAÇAO | G39: Aluguel container Banheiro | K39: 46115 | Q39: =IF(K39="","",K39) -> 46115 | R39: GESTÃO LOCAL | S39: Saída | GESTÃO LOCAL | T39: Saída | GESTÃO LOCAL | LOCAÇAO | V39: 252 | W39: Q2 | X39: 46104 | Y39: 46115 | Z39: 1140 | AA39: =IF(M39<>"",M39,Z39) -> 1140 | AB39: =IF(L39<>"","Realizado","Previsto") -> Previsto | AC39: 0.25 | AD39: 4560 | AF39: mês | AG39: 1140 | AH39: C origem: LOCAÇAO | AI39: CUSTO CASA E CRONOGRAMA PAGAMEN | AJ39: =IF(Q39<>"",Q39,IF(K39<>"",K39,"")) -> 46115 | AK39: =IF(K39<>"","Sim","") -> Sim | AL39: =IF(A39="","",TEXT(A39,"000000")&"-"&IF(C39="Entrada","CR","DB")) -> 000038-DB | AM39: =IF(A39="","",LEFT(IF(H39<>"",H39,G39)&" | "&G39&" | "&S39,60)) -> Aluguel container Banheiro | Aluguel container Banheiro | Sa
A40: 39 | B40: SÃO FRANCISCO DE PAULA - RS | C40: Saída | D40: GESTÃO LOCAL | E40: GESTÃO LOCAL | F40: LOCAÇAO | G40: Aluguel container almoxarifado | K40: 46115 | Q40: =IF(K40="","",K40) -> 46115 | R40: GESTÃO LOCAL | S40: Saída | GESTÃO LOCAL | T40: Saída | GESTÃO LOCAL | LOCAÇAO | V40: 254 | W40: Q2 | X40: 46104 | Y40: 46115 | Z40: 400 | AA40: =IF(M40<>"",M40,Z40) -> 400 | AB40: =IF(L40<>"","Realizado","Previsto") -> Previsto | AC40: 0.25 | AD40: 1600 | AF40: mês | AG40: 400 | AH40: C origem: LOCAÇAO | AI40: CUSTO CASA E CRONOGRAMA PAGAMEN | AJ40: =IF(Q40<>"",Q40,IF(K40<>"",K40,"")) -> 46115 | AK40: =IF(K40<>"","Sim","") -> Sim | AL40: =IF(A40="","",TEXT(A40,"000000")&"-"&IF(C40="Entrada","CR","DB")) -> 000039-DB | AM40: =IF(A40="","",LEFT(IF(H40<>"",H40,G40)&" | "&G40&" | "&S40,60)) -> Aluguel container almoxarifado | Aluguel container almoxarif
A41: 40 | B41: SÃO FRANCISCO DE PAULA - RS | C41: Saída | D41: GESTÃO LOCAL | E41: GESTÃO LOCAL | F41: LOCAÇAO | G41: Aluguel container escritorio | K41: 46115 | Q41: =IF(K41="","",K41) -> 46115 | R41: GESTÃO LOCAL | S41: Saída | GESTÃO LOCAL | T41: Saída | GESTÃO LOCAL | LOCAÇAO | V41: 255 | W41: Q2 | X41: 46104 | Y41: 46115 | Z41: 900 | AA41: =IF(M41<>"",M41,Z41) -> 900 | AB41: =IF(L41<>"","Realizado","Previsto") -> Previsto | AC41: 0.25 | AD41: 3600 | AF41: mês | AG41: 900 | AH41: C origem: LOCAÇAO | AI41: CUSTO CASA E CRONOGRAMA PAGAMEN | AJ41: =IF(Q41<>"",Q41,IF(K41<>"",K41,"")) -> 46115 | AK41: =IF(K41<>"","Sim","") -> Sim | AL41: =IF(A41="","",TEXT(A41,"000000")&"-"&IF(C41="Entrada","CR","DB")) -> 000040-DB | AM41: =IF(A41="","",LEFT(IF(H41<>"",H41,G41)&" | "&G41&" | "&S41,60)) -> Aluguel container escritorio | Aluguel container escritorio
A42: 41 | B42: SÃO FRANCISCO DE PAULA - RS | C42: Saída | D42: GESTÃO LOCAL | E42: GESTÃO LOCAL | F42: ADMINISTRAÇAO | G42: COMPRADOR | K42: 46115 | Q42: =IF(K42="","",K42) -> 46115 | R42: GESTÃO LOCAL | S42: Saída | GESTÃO LOCAL | T42: Saída | GESTÃO LOCAL | ADMINISTRAÇAO | U42: pra obra de 50 casa considera apenas encarregado | V42: 262 | W42: Q2 | X42: 46104 | Y42: 46115 | Z42: 3000 | AA42: =IF(M42<>"",M42,Z42) -> 3000 | AB42: =IF(L42<>"","Realizado","Previsto") -> Previsto | AC42: 0.25 | AD42: 12000 | AF42: mês | AG42: 3000 | AH42: C origem: ADMINISTRAÇAO | AI42: CUSTO CASA E CRONOGRAMA PAGAMEN | AJ42: =IF(Q42<>"",Q42,IF(K42<>"",K42,"")) -> 46115 | AK42: =IF(K42<>"","Sim","") -> Sim | AL42: =IF(A42="","",TEXT(A42,"000000")&"-"&IF(C42="Entrada","CR","DB")) -> 000041-DB | AM42: =IF(A42="","",LEFT(IF(H42<>"",H42,G42)&" | "&G42&" | "&S42,60)) -> COMPRADOR | COMPRADOR | Saída | GESTÃO LOCAL
A43: 42 | B43: SÃO FRANCISCO DE PAULA - RS | C43: Saída | D43: GESTÃO LOCAL | E43: GESTÃO LOCAL | F43: ADMINISTRAÇAO | G43: ENGENHEIRO RESIDENTE - ( rateado em 3 canteiros) carro incluso | K43: 46115 | Q43: =IF(K43="","",K43) -> 46115 | R43: GESTÃO LOCAL | S43: Saída | GESTÃO LOCAL | T43: Saída | GESTÃO LOCAL | ADMINISTRAÇAO | V43: 259 | W43: Q2 | X43: 46104 | Y43: 46115 | Z43: 10000 | AA43: =IF(M43<>"",M43,Z43) -> 10000 | AB43: =IF(L43<>"","Realizado","Previsto") -> Previsto | AC43: 0.25 | AD43: 40000 | AF43: mês | AG43: 10000 | AH43: C origem: ADMINISTRAÇAO | AI43: CUSTO CASA E CRONOGRAMA PAGAMEN | AJ43: =IF(Q43<>"",Q43,IF(K43<>"",K43,"")) -> 46115 | AK43: =IF(K43<>"","Sim","") -> Sim | AL43: =IF(A43="","",TEXT(A43,"000000")&"-"&IF(C43="Entrada","CR","DB")) -> 000042-DB | AM43: =IF(A43="","",LEFT(IF(H43<>"",H43,G43)&" | "&G43&" | "&S43,60)) -> ENGENHEIRO RESIDENTE - ( rateado em 3 canteiros) carro inclu
A44: 43 | B44: SÃO FRANCISCO DE PAULA - RS | C44: Saída | D44: RADIER - 44,38 M² | E44: RADIER | F44: FERRAGEM | G44: Arame Recozido bwg 18 | K44: 46115 | Q44: =IF(K44="","",K44) -> 46115 | R44: RADIER - 44,38 M² | S44: Saída | RADIER - 44,38 M² | T44: Saída | RADIER | FERRAGEM | V44: 36 | W44: Q2 | X44: 46104 | Y44: 46115 | Z44: 192 | AA44: =IF(M44<>"",M44,Z44) -> 192 | AB44: =IF(L44<>"","Realizado","Previsto") -> Previsto | AC44: 0.5 | AD44: 384 | AE44: 32 | AF44: kg | AG44: 12 | AH44: B origem: RADIER | C origem: FERRAGEM | AI44: CUSTO CASA E CRONOGRAMA PAGAMEN | AJ44: =IF(Q44<>"",Q44,IF(K44<>"",K44,"")) -> 46115 | AK44: =IF(K44<>"","Sim","") -> Sim | AL44: =IF(A44="","",TEXT(A44,"000000")&"-"&IF(C44="Entrada","CR","DB")) -> 000043-DB | AM44: =IF(A44="","",LEFT(IF(H44<>"",H44,G44)&" | "&G44&" | "&S44,60)) -> Arame Recozido bwg 18 | Arame Recozido bwg 18 | Saída | RADI
A45: 44 | B45: SÃO FRANCISCO DE PAULA - RS | C45: Saída | D45: RADIER - 44,38 M² | E45: RADIER | F45: FERRAGEM | G45: Aço - Tela Q-138 - 5.0 c/10 - (245 x 600 cm) (frete de 300 + ipi de 133 incluido | K45: 46115 | Q45: =IF(K45="","",K45) -> 46115 | R45: RADIER - 44,38 M² | S45: Saída | RADIER - 44,38 M² | T45: Saída | RADIER | FERRAGEM | V45: 34 | W45: Q2 | X45: 46104 | Y45: 46115 | Z45: 40821.76 | AA45: =IF(M45<>"",M45,Z45) -> 40821.76 | AB45: =IF(L45<>"","Realizado","Previsto") -> Previsto | AC45: 0.34 | AD45: 120064 | AE45: 512 | AF45: telas | AG45: 234.5 | AH45: B origem: RADIER | C origem: FERRAGEM | AI45: CUSTO CASA E CRONOGRAMA PAGAMEN | AJ45: =IF(Q45<>"",Q45,IF(K45<>"",K45,"")) -> 46115 | AK45: =IF(K45<>"","Sim","") -> Sim | AL45: =IF(A45="","",TEXT(A45,"000000")&"-"&IF(C45="Entrada","CR","DB")) -> 000044-DB | AM45: =IF(A45="","",LEFT(IF(H45<>"",H45,G45)&" | "&G45&" | "&S45,60)) -> Aço - Tela Q-138 - 5.0 c/10 - (245 x 600 cm) (frete de 300
A46: 45 | B46: SÃO FRANCISCO DE PAULA - RS | C46: Saída | D46: RADIER - 44,38 M² | E46: RADIER | F46: CONCRETO | G46: Bomba de concreto ( Taxa divide 1 casa e 1 radier ) | K46: 46115 | Q46: =IF(K46="","",K46) -> 46115 | R46: RADIER - 44,38 M² | S46: Saída | RADIER - 44,38 M² | T46: Saída | RADIER | CONCRETO | U46: 21 DIAS: uma diaria de bomba faz 3 radies por dia | V46: 30 | W46: Q2 | X46: 46104 | Y46: 46115 | Z46: 4400 | AA46: =IF(M46<>"",M46,Z46) -> 4400 | AB46: =IF(L46<>"","Realizado","Previsto") -> Previsto | AC46: 0.25 | AD46: 17600 | AE46: 8 | AF46: vb | AG46: 2200 | AH46: B origem: RADIER | C origem: CONCRETO | AI46: CUSTO CASA E CRONOGRAMA PAGAMEN | AJ46: =IF(Q46<>"",Q46,IF(K46<>"",K46,"")) -> 46115 | AK46: =IF(K46<>"","Sim","") -> Sim | AL46: =IF(A46="","",TEXT(A46,"000000")&"-"&IF(C46="Entrada","CR","DB")) -> 000045-DB | AM46: =IF(A46="","",LEFT(IF(H46<>"",H46,G46)&" | "&G46&" | "&S46,60)) -> Bomba de concreto ( Taxa divide 1 casa e 1 radier ) | Bomba
A47: 46 | B47: SÃO FRANCISCO DE PAULA - RS | C47: Saída | D47: RADIER - 44,38 M² | E47: RADIER | F47: Agregado | G47: Brita graduada (lastro para nivelamento) - 10 cm esp.; 15% penetração no solo | K47: 46115 | Q47: =IF(K47="","",K47) -> 46115 | R47: RADIER - 44,38 M² | S47: Saída | RADIER - 44,38 M² | T47: Saída | RADIER | Agregado | U47: 30/60 dias | V47: 31 | W47: Q2 | X47: 46104 | Y47: 46115 | Z47: 16921.486 | AA47: =IF(M47<>"",M47,Z47) -> 16921.486 | AB47: =IF(L47<>"","Realizado","Previsto") -> Previsto | AC47: 0.5 | AD47: 33842.973 | AE47: 371.9008 | AF47: m³ | AG47: 91 | AH47: B origem: RADIER | C origem: Agregado | AI47: CUSTO CASA E CRONOGRAMA PAGAMEN | AJ47: =IF(Q47<>"",Q47,IF(K47<>"",K47,"")) -> 46115 | AK47: =IF(K47<>"","Sim","") -> Sim | AL47: =IF(A47="","",TEXT(A47,"000000")&"-"&IF(C47="Entrada","CR","DB")) -> 000046-DB | AM47: =IF(A47="","",LEFT(IF(H47<>"",H47,G47)&" | "&G47&" | "&S47,60)) -> Brita graduada (lastro para nivelamento) - 10 cm esp.; 15% p
...

Sheet FLUXO_DIARIO
A1: Fluxo de Caixa Diário (previsto pendente + realizado)
A2: Previsto entra apenas enquanto o lançamento estiver sem Data_Realizada; depois disso ele migra para o realizado.
A3: Saldo inicial de caixa | B3: 720000 | D3: Início | E3: 46090 | F3: Fim | G3: 46287
A5: Data | B5: Entradas_Previstas_Pendentes | C5: Saidas_Previstas_Pendentes | D5: Entradas_Realizadas | E5: Saidas_Realizadas | F5: Movimento_Liquido_Dia | G5: Saldo_Acumulado | H5: Observacao
A6: 46090 | B6: =SUMIFS(BASE_CAIXA!$Z$2:$Z$643,BASE_CAIXA!$C$2:$C$643,"Entrada",BASE_CAIXA!$K$2:$K$643,A6,BASE_CAIXA!$L$2:$L$643,"") -> 0 | C6: =SUMIFS(BASE_CAIXA!$Z$2:$Z$643,BASE_CAIXA!$C$2:$C$643,"Saída",BASE_CAIXA!$K$2:$K$643,A6,BASE_CAIXA!$L$2:$L$643,"") -> 32000 | D6: =SUMIFS(BASE_CAIXA!$AA$2:$AA$643,BASE_CAIXA!$C$2:$C$643,"Entrada",BASE_CAIXA!$L$2:$L$643,A6) -> 0 | E6: =SUMIFS(BASE_CAIXA!$AA$2:$AA$643,BASE_CAIXA!$C$2:$C$643,"Saída",BASE_CAIXA!$L$2:$L$643,A6) -> 0 | F6: =B6-C6+D6-E6 -> -32000 | G6: =$B$3+F6 -> 688000
A7: 46091 | B7: =SUMIFS(BASE_CAIXA!$Z$2:$Z$643,BASE_CAIXA!$C$2:$C$643,"Entrada",BASE_CAIXA!$K$2:$K$643,A7,BASE_CAIXA!$L$2:$L$643,"") -> 0 | C7: =SUMIFS(BASE_CAIXA!$Z$2:$Z$643,BASE_CAIXA!$C$2:$C$643,"Saída",BASE_CAIXA!$K$2:$K$643,A7,BASE_CAIXA!$L$2:$L$643,"") -> 0 | D7: =SUMIFS(BASE_CAIXA!$AA$2:$AA$643,BASE_CAIXA!$C$2:$C$643,"Entrada",BASE_CAIXA!$L$2:$L$643,A7) -> 0 | E7: =SUMIFS(BASE_CAIXA!$AA$2:$AA$643,BASE_CAIXA!$C$2:$C$643,"Saída",BASE_CAIXA!$L$2:$L$643,A7) -> 0 | F7: =B7-C7+D7-E7 -> 0 | G7: =G6+F7 -> 688000
A8: 46092 | B8: =SUMIFS(BASE_CAIXA!$Z$2:$Z$643,BASE_CAIXA!$C$2:$C$643,"Entrada",BASE_CAIXA!$K$2:$K$643,A8,BASE_CAIXA!$L$2:$L$643,"") -> 0 | C8: =SUMIFS(BASE_CAIXA!$Z$2:$Z$643,BASE_CAIXA!$C$2:$C$643,"Saída",BASE_CAIXA!$K$2:$K$643,A8,BASE_CAIXA!$L$2:$L$643,"") -> 68500 | D8: =SUMIFS(BASE_CAIXA!$AA$2:$AA$643,BASE_CAIXA!$C$2:$C$643,"Entrada",BASE_CAIXA!$L$2:$L$643,A8) -> 0 | E8: =SUMIFS(BASE_CAIXA!$AA$2:$AA$643,BASE_CAIXA!$C$2:$C$643,"Saída",BASE_CAIXA!$L$2:$L$643,A8) -> 0 | F8: =B8-C8+D8-E8 -> -68500 | G8: =G7+F8 -> 619500
A9: 46093 | B9: =SUMIFS(BASE_CAIXA!$Z$2:$Z$643,BASE_CAIXA!$C$2:$C$643,"Entrada",BASE_CAIXA!$K$2:$K$643,A9,BASE_CAIXA!$L$2:$L$643,"") -> 0 | C9: =SUMIFS(BASE_CAIXA!$Z$2:$Z$643,BASE_CAIXA!$C$2:$C$643,"Saída",BASE_CAIXA!$K$2:$K$643,A9,BASE_CAIXA!$L$2:$L$643,"") -> 0 | D9: =SUMIFS(BASE_CAIXA!$AA$2:$AA$643,BASE_CAIXA!$C$2:$C$643,"Entrada",BASE_CAIXA!$L$2:$L$643,A9) -> 0 | E9: =SUMIFS(BASE_CAIXA!$AA$2:$AA$643,BASE_CAIXA!$C$2:$C$643,"Saída",BASE_CAIXA!$L$2:$L$643,A9) -> 0 | F9: =B9-C9+D9-E9 -> 0 | G9: =G8+F9 -> 619500
A10: 46094 | B10: =SUMIFS(BASE_CAIXA!$Z$2:$Z$643,BASE_CAIXA!$C$2:$C$643,"Entrada",BASE_CAIXA!$K$2:$K$643,A10,BASE_CAIXA!$L$2:$L$643,"") -> 0 | C10: =SUMIFS(BASE_CAIXA!$Z$2:$Z$643,BASE_CAIXA!$C$2:$C$643,"Saída",BASE_CAIXA!$K$2:$K$643,A10,BASE_CAIXA!$L$2:$L$643,"") -> 0 | D10: =SUMIFS(BASE_CAIXA!$AA$2:$AA$643,BASE_CAIXA!$C$2:$C$643,"Entrada",BASE_CAIXA!$L$2:$L$643,A10) -> 0 | E10: =SUMIFS(BASE_CAIXA!$AA$2:$AA$643,BASE_CAIXA!$C$2:$C$643,"Saída",BASE_CAIXA!$L$2:$L$643,A10) -> 0 | F10: =B10-C10+D10-E10 -> 0 | G10: =G9+F10 -> 619500
A11: 46095 | B11: =SUMIFS(BASE_CAIXA!$Z$2:$Z$643,BASE_CAIXA!$C$2:$C$643,"Entrada",BASE_CAIXA!$K$2:$K$643,A11,BASE_CAIXA!$L$2:$L$643,"") -> 0 | C11: =SUMIFS(BASE_CAIXA!$Z$2:$Z$643,BASE_CAIXA!$C$2:$C$643,"Saída",BASE_CAIXA!$K$2:$K$643,A11,BASE_CAIXA!$L$2:$L$643,"") -> 0 | D11: =SUMIFS(BASE_CAIXA!$AA$2:$AA$643,BASE_CAIXA!$C$2:$C$643,"Entrada",BASE_CAIXA!$L$2:$L$643,A11) -> 0 | E11: =SUMIFS(BASE_CAIXA!$AA$2:$AA$643,BASE_CAIXA!$C$2:$C$643,"Saída",BASE_CAIXA!$L$2:$L$643,A11) -> 0 | F11: =B11-C11+D11-E11 -> 0 | G11: =G10+F11 -> 619500
A12: 46096 | B12: =SUMIFS(BASE_CAIXA!$Z$2:$Z$643,BASE_CAIXA!$C$2:$C$643,"Entrada",BASE_CAIXA!$K$2:$K$643,A12,BASE_CAIXA!$L$2:$L$643,"") -> 0 | C12: =SUMIFS(BASE_CAIXA!$Z$2:$Z$643,BASE_CAIXA!$C$2:$C$643,"Saída",BASE_CAIXA!$K$2:$K$643,A12,BASE_CAIXA!$L$2:$L$643,"") -> 0 | D12: =SUMIFS(BASE_CAIXA!$AA$2:$AA$643,BASE_CAIXA!$C$2:$C$643,"Entrada",BASE_CAIXA!$L$2:$L$643,A12) -> 0 | E12: =SUMIFS(BASE_CAIXA!$AA$2:$AA$643,BASE_CAIXA!$C$2:$C$643,"Saída",BASE_CAIXA!$L$2:$L$643,A12) -> 0 | F12: =B12-C12+D12-E12 -> 0 | G12: =G11+F12 -> 619500
A13: 46097 | B13: =SUMIFS(BASE_CAIXA!$Z$2:$Z$643,BASE_CAIXA!$C$2:$C$643,"Entrada",BASE_CAIXA!$K$2:$K$643,A13,BASE_CAIXA!$L$2:$L$643,"") -> 0 | C13: =SUMIFS(BASE_CAIXA!$Z$2:$Z$643,BASE_CAIXA!$C$2:$C$643,"Saída",BASE_CAIXA!$K$2:$K$643,A13,BASE_CAIXA!$L$2:$L$643,"") -> 0 | D13: =SUMIFS(BASE_CAIXA!$AA$2:$AA$643,BASE_CAIXA!$C$2:$C$643,"Entrada",BASE_CAIXA!$L$2:$L$643,A13) -> 0 | E13: =SUMIFS(BASE_CAIXA!$AA$2:$AA$643,BASE_CAIXA!$C$2:$C$643,"Saída",BASE_CAIXA!$L$2:$L$643,A13) -> 0 | F13: =B13-C13+D13-E13 -> 0 | G13: =G12+F13 -> 619500
A14: 46098 | B14: =SUMIFS(BASE_CAIXA!$Z$2:$Z$643,BASE_CAIXA!$C$2:$C$643,"Entrada",BASE_CAIXA!$K$2:$K$643,A14,BASE_CAIXA!$L$2:$L$643,"") -> 0 | C14: =SUMIFS(BASE_CAIXA!$Z$2:$Z$643,BASE_CAIXA!$C$2:$C$643,"Saída",BASE_CAIXA!$K$2:$K$643,A14,BASE_CAIXA!$L$2:$L$643,"") -> 0 | D14: =SUMIFS(BASE_CAIXA!$AA$2:$AA$643,BASE_CAIXA!$C$2:$C$643,"Entrada",BASE_CAIXA!$L$2:$L$643,A14) -> 0 | E14: =SUMIFS(BASE_CAIXA!$AA$2:$AA$643,BASE_CAIXA!$C$2:$C$643,"Saída",BASE_CAIXA!$L$2:$L$643,A14) -> 0 | F14: =B14-C14+D14-E14 -> 0 | G14: =G13+F14 -> 619500
A15: 46099 | B15: =SUMIFS(BASE_CAIXA!$Z$2:$Z$643,BASE_CAIXA!$C$2:$C$643,"Entrada",BASE_CAIXA!$K$2:$K$643,A15,BASE_CAIXA!$L$2:$L$643,"") -> 0 | C15: =SUMIFS(BASE_CAIXA!$Z$2:$Z$643,BASE_CAIXA!$C$2:$C$643,"Saída",BASE_CAIXA!$K$2:$K$643,A15,BASE_CAIXA!$L$2:$L$643,"") -> 0 | D15: =SUMIFS(BASE_CAIXA!$AA$2:$AA$643,BASE_CAIXA!$C$2:$C$643,"Entrada",BASE_CAIXA!$L$2:$L$643,A15) -> 0 | E15: =SUMIFS(BASE_CAIXA!$AA$2:$AA$643,BASE_CAIXA!$C$2:$C$643,"Saída",BASE_CAIXA!$L$2:$L$643,A15) -> 0 | F15: =B15-C15+D15-E15 -> 0 | G15: =G14+F15 -> 619500
A16: 46100 | B16: =SUMIFS(BASE_CAIXA!$Z$2:$Z$643,BASE_CAIXA!$C$2:$C$643,"Entrada",BASE_CAIXA!$K$2:$K$643,A16,BASE_CAIXA!$L$2:$L$643,"") -> 0 | C16: =SUMIFS(BASE_CAIXA!$Z$2:$Z$643,BASE_CAIXA!$C$2:$C$643,"Saída",BASE_CAIXA!$K$2:$K$643,A16,BASE_CAIXA!$L$2:$L$643,"") -> 0 | D16: =SUMIFS(BASE_CAIXA!$AA$2:$AA$643,BASE_CAIXA!$C$2:$C$643,"Entrada",BASE_CAIXA!$L$2:$L$643,A16) -> 0 | E16: =SUMIFS(BASE_CAIXA!$AA$2:$AA$643,BASE_CAIXA!$C$2:$C$643,"Saída",BASE_CAIXA!$L$2:$L$643,A16) -> 0 | F16: =B16-C16+D16-E16 -> 0 | G16: =G15+F16 -> 619500
A17: 46101 | B17: =SUMIFS(BASE_CAIXA!$Z$2:$Z$643,BASE_CAIXA!$C$2:$C$643,"Entrada",BASE_CAIXA!$K$2:$K$643,A17,BASE_CAIXA!$L$2:$L$643,"") -> 0 | C17: =SUMIFS(BASE_CAIXA!$Z$2:$Z$643,BASE_CAIXA!$C$2:$C$643,"Saída",BASE_CAIXA!$K$2:$K$643,A17,BASE_CAIXA!$L$2:$L$643,"") -> 695979.2 | D17: =SUMIFS(BASE_CAIXA!$AA$2:$AA$643,BASE_CAIXA!$C$2:$C$643,"Entrada",BASE_CAIXA!$L$2:$L$643,A17) -> 0 | E17: =SUMIFS(BASE_CAIXA!$AA$2:$AA$643,BASE_CAIXA!$C$2:$C$643,"Saída",BASE_CAIXA!$L$2:$L$643,A17) -> 0 | F17: =B17-C17+D17-E17 -> -695979.2 | G17: =G16+F17 -> -76479.2
A18: 46102 | B18: =SUMIFS(BASE_CAIXA!$Z$2:$Z$643,BASE_CAIXA!$C$2:$C$643,"Entrada",BASE_CAIXA!$K$2:$K$643,A18,BASE_CAIXA!$L$2:$L$643,"") -> 0 | C18: =SUMIFS(BASE_CAIXA!$Z$2:$Z$643,BASE_CAIXA!$C$2:$C$643,"Saída",BASE_CAIXA!$K$2:$K$643,A18,BASE_CAIXA!$L$2:$L$643,"") -> 0 | D18: =SUMIFS(BASE_CAIXA!$AA$2:$AA$643,BASE_CAIXA!$C$2:$C$643,"Entrada",BASE_CAIXA!$L$2:$L$643,A18) -> 0 | E18: =SUMIFS(BASE_CAIXA!$AA$2:$AA$643,BASE_CAIXA!$C$2:$C$643,"Saída",BASE_CAIXA!$L$2:$L$643,A18) -> 0 | F18: =B18-C18+D18-E18 -> 0 | G18: =G17+F18 -> -76479.2
... A203: 46287 | B203: =SUMIFS(BASE_CAIXA!$Z$2:$Z$643,BASE_CAIXA!$C$2:$C$643,"Entrada",BASE_CAIXA!$K$2:$K$643,A203,BASE_CAIXA!$L$2:$L$643,"") -> 0 | C203: =SUMIFS(BASE_CAIXA!$Z$2:$Z$643,BASE_CAIXA!$C$2:$C$643,"Saída",BASE_CAIXA!$K$2:$K$643,A203,BASE_CAIXA!$L$2:$L$643,"") -> 0 | D203: =SUMIFS(BASE_CAIXA!$AA$2:$AA$643,BASE_CAIXA!$C$2:$C$643,"Entrada",BASE_CAIXA!$L$2:$L$643,A203) -> 0 | E203: =SUMIFS(BASE_CAIXA!$AA$2:$AA$643,BASE_CAIXA!$C$2:$C$643,"Saída",BASE_CAIXA!$L$2:$L$643,A203) -> 0 | F203: =B203-C203+D203-E203 -> 0 | G203: =G202+F203 -> -4504668.4
A204: TOTAL | B204: =SUM(B6:B203) -> 7359999.9 | C204: =SUM(C6:C203) -> 12584668 | D204: =SUM(D6:D203) -> 0 | E204: =SUM(E6:E203) -> 0 | F204: =SUM(F6:F203) -> -5224668.4 | G204: =G203 -> -4504668.4

Sheet SAUDE_FLUXO
A1: Saúde do Fluxo de Caixa
A3: Indicador | B3: Valor | D3: Observação
A4: Saldo inicial | B4: =FLUXO_DIARIO!B3 -> 720000 | D4: Preenchimento manual
A5: Entradas previstas pendentes | B5: =SUM(FLUXO_DIARIO!B6:B203) -> 7359999.9 | D5: Ainda não realizadas
A6: Saídas previstas pendentes | B6: =SUM(FLUXO_DIARIO!C6:C203) -> 12584668 | D6: Ainda não realizadas
A7: Entradas realizadas | B7: =SUM(FLUXO_DIARIO!D6:D203) -> 0 | D7: Baixadas na base
A8: Saídas realizadas | B8: =SUM(FLUXO_DIARIO!E6:E203) -> 0 | D8: Baixadas na base
A9: Caixa final projetado | B9: =FLUXO_DIARIO!G203 -> -4504668.4 | D9: Saldo ao fim do horizonte
A10: Pior saldo projetado | B10: =MIN(FLUXO_DIARIO!G6:G203) -> -4504668.4 | D10: Menor saldo acumulado
A11: Data do pior saldo | B11: =INDEX(FLUXO_DIARIO!A6:A203,MATCH(MIN(FLUXO_DIARIO!G6:G203),FLUXO_DIARIO!G6:G203,0)) -> 46227 | D11: Quando o caixa fica mais pressionado
A12: Dias com saldo negativo | B12: =COUNTIF(FLUXO_DIARIO!G6:G203,"<0") -> 187 | D12: Dias em que o caixa projetado fica abaixo de zero
A13: Cobertura de entradas vs saídas | B13: =IFERROR((SUM(FLUXO_DIARIO!B6:B203)+SUM(FLUXO_DIARIO!D6:D203))/(SUM(FLUXO_DIARIO!C6:C203)+SUM(FLUXO_DIARIO!E6:E203)),0) -> 0.58483861 | D13: Acima de 1,0x é mais confortável
A16: Data | B16: Entradas Totais do Dia | C16: Saídas Totais do Dia | D16: Líquido do Dia | E16: Saldo Acumulado | F16: Cobertura do Dia | G16: Status
A17: =FLUXO_DIARIO!A6 -> 46090 | B17: =FLUXO_DIARIO!B6+FLUXO_DIARIO!D6 -> 0 | C17: =FLUXO_DIARIO!C6+FLUXO_DIARIO!E6 -> 32000 | D17: =B17-C17 -> -32000 | E17: =FLUXO_DIARIO!G6 -> 688000 | F17: =IFERROR(B17/C17,0) -> 0 | G17: =IF(E17<0,"Crítico",IF(F17<1,"Atenção","Saudável")) -> Atenção
A18: =FLUXO_DIARIO!A7 -> 46091 | B18: =FLUXO_DIARIO!B7+FLUXO_DIARIO!D7 -> 0 | C18: =FLUXO_DIARIO!C7+FLUXO_DIARIO!E7 -> 0 | D18: =B18-C18 -> 0 | E18: =FLUXO_DIARIO!G7 -> 688000 | F18: =IFERROR(B18/C18,0) -> 0 | G18: =IF(E18<0,"Crítico",IF(F18<1,"Atenção","Saudável")) -> Atenção
A19: =FLUXO_DIARIO!A8 -> 46092 | B19: =FLUXO_DIARIO!B8+FLUXO_DIARIO!D8 -> 0 | C19: =FLUXO_DIARIO!C8+FLUXO_DIARIO!E8 -> 68500 | D19: =B19-C19 -> -68500 | E19: =FLUXO_DIARIO!G8 -> 619500 | F19: =IFERROR(B19/C19,0) -> 0 | G19: =IF(E19<0,"Crítico",IF(F19<1,"Atenção","Saudável")) -> Atenção
A20: =FLUXO_DIARIO!A9 -> 46093 | B20: =FLUXO_DIARIO!B9+FLUXO_DIARIO!D9 -> 0 | C20: =FLUXO_DIARIO!C9+FLUXO_DIARIO!E9 -> 0 | D20: =B20-C20 -> 0 | E20: =FLUXO_DIARIO!G9 -> 619500 | F20: =IFERROR(B20/C20,0) -> 0 | G20: =IF(E20<0,"Crítico",IF(F20<1,"Atenção","Saudável")) -> Atenção
A21: =FLUXO_DIARIO!A10 -> 46094 | B21: =FLUXO_DIARIO!B10+FLUXO_DIARIO!D10 -> 0 | C21: =FLUXO_DIARIO!C10+FLUXO_DIARIO!E10 -> 0 | D21: =B21-C21 -> 0 | E21: =FLUXO_DIARIO!G10 -> 619500 | F21: =IFERROR(B21/C21,0) -> 0 | G21: =IF(E21<0,"Crítico",IF(F21<1,"Atenção","Saudável")) -> Atenção
A22: =FLUXO_DIARIO!A11 -> 46095 | B22: =FLUXO_DIARIO!B11+FLUXO_DIARIO!D11 -> 0 | C22: =FLUXO_DIARIO!C11+FLUXO_DIARIO!E11 -> 0 | D22: =B22-C22 -> 0 | E22: =FLUXO_DIARIO!G11 -> 619500 | F22: =IFERROR(B22/C22,0) -> 0 | G22: =IF(E22<0,"Crítico",IF(F22<1,"Atenção","Saudável")) -> Atenção
A23: =FLUXO_DIARIO!A12 -> 46096 | B23: =FLUXO_DIARIO!B12+FLUXO_DIARIO!D12 -> 0 | C23: =FLUXO_DIARIO!C12+FLUXO_DIARIO!E12 -> 0 | D23: =B23-C23 -> 0 | E23: =FLUXO_DIARIO!G12 -> 619500 | F23: =IFERROR(B23/C23,0) -> 0 | G23: =IF(E23<0,"Crítico",IF(F23<1,"Atenção","Saudável")) -> Atenção
A24: =FLUXO_DIARIO!A13 -> 46097 | B24: =FLUXO_DIARIO!B13+FLUXO_DIARIO!D13 -> 0 | C24: =FLUXO_DIARIO!C13+FLUXO_DIARIO!E13 -> 0 | D24: =B24-C24 -> 0 | E24: =FLUXO_DIARIO!G13 -> 619500 | F24: =IFERROR(B24/C24,0) -> 0 | G24: =IF(E24<0,"Crítico",IF(F24<1,"Atenção","Saudável")) -> Atenção
A25: =FLUXO_DIARIO!A14 -> 46098 | B25: =FLUXO_DIARIO!B14+FLUXO_DIARIO!D14 -> 0 | C25: =FLUXO_DIARIO!C14+FLUXO_DIARIO!E14 -> 0 | D25: =B25-C25 -> 0 | E25: =FLUXO_DIARIO!G14 -> 619500 | F25: =IFERROR(B25/C25,0) -> 0 | G25: =IF(E25<0,"Crítico",IF(F25<1,"Atenção","Saudável")) -> Atenção
A26: =FLUXO_DIARIO!A15 -> 46099 | B26: =FLUXO_DIARIO!B15+FLUXO_DIARIO!D15 -> 0 | C26: =FLUXO_DIARIO!C15+FLUXO_DIARIO!E15 -> 0 | D26: =B26-C26 -> 0 | E26: =FLUXO_DIARIO!G15 -> 619500 | F26: =IFERROR(B26/C26,0) -> 0 | G26: =IF(E26<0,"Crítico",IF(F26<1,"Atenção","Saudável")) -> Atenção
A27: =FLUXO_DIARIO!A16 -> 46100 | B27: =FLUXO_DIARIO!B16+FLUXO_DIARIO!D16 -> 0 | C27: =FLUXO_DIARIO!C16+FLUXO_DIARIO!E16 -> 0 | D27: =B27-C27 -> 0 | E27: =FLUXO_DIARIO!G16 -> 619500 | F27: =IFERROR(B27/C27,0) -> 0 | G27: =IF(E27<0,"Crítico",IF(F27<1,"Atenção","Saudável")) -> Atenção
A28: =FLUXO_DIARIO!A17 -> 46101 | B28: =FLUXO_DIARIO!B17+FLUXO_DIARIO!D17 -> 0 | C28: =FLUXO_DIARIO!C17+FLUXO_DIARIO!E17 -> 695979.2 | D28: =B28-C28 -> -695979.2 | E28: =FLUXO_DIARIO!G17 -> -76479.2 | F28: =IFERROR(B28/C28,0) -> 0 | G28: =IF(E28<0,"Crítico",IF(F28<1,"Atenção","Saudável")) -> Crítico
... A214: =FLUXO_DIARIO!A203 -> 46287 | B214: =FLUXO_DIARIO!B203+FLUXO_DIARIO!D203 -> 0 | C214: =FLUXO_DIARIO!C203+FLUXO_DIARIO!E203 -> 0 | D214: =B214-C214 -> 0 | E214: =FLUXO_DIARIO!G203 -> -4504668.4 | F214: =IFERROR(B214/C214,0) -> 0 | G214: =IF(E214<0,"Crítico",IF(F214<1,"Atenção","Saudável")) -> Crítico

Sheet ORIGEM_RESUMIDA
B1: MUNICÍPIO: | C1: SÃO FRANCISCO DE PAULA - RS | J1: CUSTO 1 CASA: | L1: 273760.4 | M1: 13593.584 | N1: 221803.69 | O1: 92553.388 | P1: 77621.623 | Q1: 161585.88 | R1: 617320.47 | S1: 973107.25 | T1: 1254450.2 | U1: 1276242.9 | V1: 273760.4 | W1: 13593.584 | X1: 221803.69 | Y1: 92553.388 | Z1: 77621.623 | AA1: 161585.88 | AB1: 617320.47 | AC1: 973107.25 | AD1: 1254450.2 | AE1: 1276242.9
B2: QUANTIDADE CASAS | C2: 64 | J2: 90594.325 | L2: 46090 | M2: 46104 | N2: 46118 | O2: 46132 | P2: 46146 | Q2: 46160 | R2: 46174 | S2: 46188 | T2: 46202 | U2: 46216 | V2: 46090 | W2: 46104 | X2: 46118 | Y2: 46132 | Z2: 46146 | AA2: 46160 | AB2: 46174 | AC2: 46188 | AD2: 46202 | AE2: 46216
B3: ESCOPO | C3: MATERIAL CONSTRUÇÃO CASA 44,33m2 | L3: 46101 | M3: 46115 | N3: 46129 | O3: 46143 | P3: 46157 | Q3: 46171 | R3: 46185 | S3: 46199 | T3: 46213 | U3: 46227 | V3: 46101 | W3: 46115 | X3: 46129 | Y3: 46143 | Z3: 46157 | AA3: 46171 | AB3: 46185 | AC3: 46199 | AD3: 46213 | AE3: 46227
B4: SEMANA INÍCIO OBRAS: | C4: 46090 | K4: 64 CASAS | L4: DISTRIBUIÇÃO PAGAMENTO PERCENTUAL (%) | V4: DISTRIBUIÇÃO PAGAMENTO FINANCEIRO (R$)
B5: APROPIAÇÃO | C5: TIPO | D5: ITEM | E5: OBSERVAÇÕES | F5: QUANT. TOTAL | G5: UN. | H5: QUANT. UNIT | I5: CUSTO UNIT. | J5: CUSTO CASA | K5: CUSTO TOTAL | L5: Q. 1 | M5: Q. 2 | N5: Q. 3 | O5: Q. 4 | P5: Q. 5 | Q5: Q. 6 | R5: Q. 7 | S5: Q. 8 | T5: Q. 9 | U5: Q. 10 | V5: Q. 1 | W5: Q. 2 | X5: Q. 3 | Y5: Q. 4 | Z5: Q. 5 | AA5: Q. 6 | AB5: Q. 7 | AC5: Q. 8 | AD5: Q. 9 | AE5: Q. 10
D6: ESPERAS DE ESGOTO RADIER | J6: 0 | K6: 0 | V6: 0 | W6: 0 | X6: 0 | Y6: 0 | Z6: 0 | AA6: 0 | AB6: 0 | AC6: 0 | AD6: 0 | AE6: 0
B7: ESPERAS DE ESGOTO RADIER | C7: Tubos e conexoes | D7: Tubo PVC DN 40mm branco rígido para esgoto sanitário | F7: 117.76 | G7: m | H7: 1.84 | I7: 3.59 | J7: 6.6056 | K7: 422.7584 | L7: 0 | M7: 0.34 | O7: 0.33 | Q7: 0.33 | V7: 0 | W7: 143.73786 | X7: 0 | Y7: 139.51027 | Z7: 0 | AA7: 139.51027 | AB7: 0 | AC7: 0 | AD7: 0 | AE7: 0
B8: ESPERAS DE ESGOTO RADIER | C8: Tubos e conexoes | D8: Tubo PVC DN 50mm branco rígido para esgoto sanitário | F8: 584.96 | G8: m | H8: 9.14 | I8: 5.69 | J8: 52.0066 | K8: 3328.4224 | L8: 0 | M8: 0.34 | O8: 0.33 | Q8: 0.33 | V8: 0 | W8: 1131.6636 | X8: 0 | Y8: 1098.3794 | Z8: 0 | AA8: 1098.3794 | AB8: 0 | AC8: 0 | AD8: 0 | AE8: 0
B9: ESPERAS DE ESGOTO RADIER | C9: Tubos e conexoes | D9: Tubo PVC DN 75mm branco rígido para esgoto sanitário | F9: 22.4 | G9: m | H9: 0.35 | I9: 10.82 | J9: 3.787 | K9: 242.368 | L9: 0 | M9: 0.34 | O9: 0.33 | Q9: 0.33 | V9: 0 | W9: 82.40512 | X9: 0 | Y9: 79.98144 | Z9: 0 | AA9: 79.98144 | AB9: 0 | AC9: 0 | AD9: 0 | AE9: 0
B10: ESPERAS DE ESGOTO RADIER | C10: Tubos e conexoes | D10: Tubo PVC DN 100mm branco rígido para esgoto sanitário | F10: 140.8 | G10: m | H10: 2.2 | I10: 15.98 | J10: 35.156 | K10: 2249.984 | L10: 0 | M10: 0.34 | O10: 0.33 | Q10: 0.33 | V10: 0 | W10: 764.99456 | X10: 0 | Y10: 742.49472 | Z10: 0 | AA10: 742.49472 | AB10: 0 | AC10: 0 | AD10: 0 | AE10: 0
B11: ESPERAS DE ESGOTO RADIER | C11: Tubos e conexoes | D11: Joelho 90º PVC DN 100mm branco rígido para esgoto sanitário predial | F11: 64 | G11: unidade | H11: 1 | I11: 13.99 | J11: 13.99 | K11: 895.36 | L11: 0 | M11: 0.34 | O11: 0.33 | Q11: 0.33 | V11: 0 | W11: 304.4224 | X11: 0 | Y11: 295.4688 | Z11: 0 | AA11: 295.4688 | AB11: 0 | AC11: 0 | AD11: 0 | AE11: 0
B12: ESPERAS DE ESGOTO RADIER | C12: Tubos e conexoes | D12: Joelho 90º PVC DN 40mm branco rígido para esgoto sanitário predial | F12: 128 | G12: unidade | H12: 2 | I12: 3.09 | J12: 6.18 | K12: 395.52 | L12: 0 | M12: 0.34 | O12: 0.33 | Q12: 0.33 | V12: 0 | W12: 134.4768 | X12: 0 | Y12: 130.5216 | Z12: 0 | AA12: 130.5216 | AB12: 0 | AC12: 0 | AD12: 0 | AE12: 0
B13: ESPERAS DE ESGOTO RADIER | C13: Tubos e conexoes | D13: Joelho 45º PVC DN 40mm branco rígido para esgoto sanitário predial | F13: 64 | G13: unidade | H13: 1 | I13: 1.4 | J13: 1.4 | K13: 89.6 | L13: 0 | M13: 0.34 | O13: 0.33 | Q13: 0.33 | V13: 0 | W13: 30.464 | X13: 0 | Y13: 29.568 | Z13: 0 | AA13: 29.568 | AB13: 0 | AC13: 0 | AD13: 0 | AE13: 0
B14: ESPERAS DE ESGOTO RADIER | C14: Tubos e conexoes | D14: Joelho 90º PVC DN 50mm branco junta elástica para esgoto sanitário | F14: 384 | G14: unidade | H14: 6 | I14: 5.72 | J14: 34.32 | K14: 2196.48 | L14: 0 | M14: 0.34 | O14: 0.33 | Q14: 0.33 | V14: 0 | W14: 746.8032 | X14: 0 | Y14: 724.8384 | Z14: 0 | AA14: 724.8384 | AB14: 0 | AC14: 0 | AD14: 0 | AE14: 0
B15: ESPERAS DE ESGOTO RADIER | C15: Tubos e conexoes | D15: Joelho 45º PVC DN 50mm branco rígido para esgoto sanitário predial | F15: 64 | G15: unidade | H15: 1 | I15: 6 | J15: 6 | K15: 384 | L15: 0 | M15: 0.34 | O15: 0.33 | Q15: 0.33 | V15: 0 | W15: 130.56 | X15: 0 | Y15: 126.72 | Z15: 0 | AA15: 126.72 | AB15: 0 | AC15: 0 | AD15: 0 | AE15: 0
B16: ESPERAS DE ESGOTO RADIER | C16: Tubos e conexoes | D16: Junção simples PVC DN 50x50mm branco rígido para esgoto sanitário predial | F16: 64 | G16: unidade | H16: 1 | I16: 17.98 | J16: 17.98 | K16: 1150.72 | L16: 0 | M16: 0.34 | O16: 0.33 | Q16: 0.33 | V16: 0 | W16: 391.2448 | X16: 0 | Y16: 379.7376 | Z16: 0 | AA16: 379.7376 | AB16: 0 | AC16: 0 | AD16: 0 | AE16: 0
B17: ESPERAS DE ESGOTO RADIER | C17: Tubos e conexoes | D17: Junção de Redução invertica PVC DN 100x50mm branco rígido para esgoto sanitário predial | F17: 64 | G17: unidade | H17: 1 | I17: 21.56 | J17: 21.56 | K17: 1379.84 | L17: 0 | M17: 0.34 | O17: 0.33 | Q17: 0.33 | V17: 0 | W17: 469.1456 | X17: 0 | Y17: 455.3472 | Z17: 0 | AA17: 455.3472 | AB17: 0 | AC17: 0 | AD17: 0 | AE17: 0
B18: ESPERAS DE ESGOTO RADIER | C18: Tubos e conexoes | D18: TE DN 50x50mm PVC branco rígido para esgoto sanitário predial | F18: 64 | G18: unidade | H18: 1 | I18: 4.96 | J18: 4.96 | K18: 317.44 | L18: 0 | M18: 0.34 | O18: 0.33 | Q18: 0.33 | V18: 0 | W18: 107.9296 | X18: 0 | Y18: 104.7552 | Z18: 0 | AA18: 104.7552 | AB18: 0 | AC18: 0 | AD18: 0 | AE18: 0
... B26: ESPERAS DE ESGOTO RADIER | C26: Tubos e conexoes | D26: Tubo DN 25 mm, PVC Rígido Soldável Marrom | F26: 64 | G26: Barra | H26: 1 | I26: 16.07 | J26: 16.07 | K26: 1028.48 | L26: 0 | M26: 0.34 | O26: 0.33 | Q26: 0.33 | V26: 0 | W26: 349.6832 | X26: 0 | Y26: 339.3984 | Z26: 0 | AA26: 339.3984 | AB26: 0 | AC26: 0 | AD26: 0 | AE26: 0
B27: ESPERAS DE ESGOTO RADIER | C27: MAO DE OBRA | D27: Mao de obra Terceirizada Hidrosanitario Radier | E27: EMPREITA: PAGTO EM 45 DIAS APÓS BOLETIM DE FISCALIZAÇÃO | F27: 64 | G27: vb | H27: 1 | I27: 0 | J27: 0 | K27: 0 | V27: 0 | W27: 0 | X27: 0 | Y27: 0 | Z27: 0 | AA27: 0 | AB27: 0 | AC27: 0 | AD27: 0 | AE27: 0
D28: RADIER - 44,38 M² | E28: 16 radiers por semana | F28: 0 | J28: 0 | K28: 0 | V28: 0 | W28: 0 | X28: 0 | Y28: 0 | Z28: 0 | AA28: 0 | AB28: 0 | AC28: 0 | AD28: 0 | AE28: 0
B29: RADIER | C29: CONCRETO | D29: Concreto Usinado fck - 25 Mpa ( Com perda de 10%) - SEM IMPERMEABILIZANTE - 140 +- 30 slump | E29: 21 DIAS | F29: 512 | G29: m³ | H29: 8 | I29: 622.15 | J29: 4977.2 | K29: 318540.8 | M29: 0.25 | N29: 0.25 | O29: 0.25 | P29: 0.25 | V29: 0 | W29: 79635.2 | X29: 79635.2 | Y29: 79635.2 | Z29: 79635.2 | AA29: 0 | AB29: 0 | AC29: 0 | AD29: 0 | AE29: 0
